Workbook

Sheet Read Me
A1: OCEANCO / Y700 SERIES VESSEL & PARTICULARS REGISTER
A3: PUBLIC-SOURCE WORKING REGISTER • 25 SEPTEMBER 2026 • VERSION 1.1 (AUDITED)
A5: IDENTIFIED VESSELS | C5: MMSI RECORDS | E5: FIRST DELIVERY | G5: LATEST DELIVERY
A6: =COUNTA('Vessel Register'!B5:B26) -> 22 | C6: =COUNTA('Vessel Register'!G5:G26) -> 22 | E6: =MIN('Vessel Register'!D5:D26) -> 2007 | G6: =MAX('Vessel Register'!D5:D26) -> 2025
A9: Scope: “seven series” is interpreted as Oceanco's Y7xx build family. The register maps 22 identified vessels between Y701 and Y726, delivered from 2007 to 2025. Y713, Y723, Y724 and Y725 remain unmapped; no project status is inferred from those gaps.
A12: WORKSHEET | C12: WHAT IT CONTAINS
A13: Vessel Register | C13: One row per IMO: name history, yard code, radio identity, flag, delivery year, overall dimensions, GT and source links.
A14: Technical Particulars | C14: Comparable draft, machinery, materials, design, performance and accommodation fields where supported.
A15: Source Comparison | C15: Selected public figures beside raw database values, with formula-driven differences and review flags.
A16: Build Sequence | C16: A slot-by-slot Y701–Y726 cross-reference, including the four unresolved number gaps.
A17: Field Evidence | C17: Every captured observation linked to its source, units, current/historical basis and caveat.
A18: Sources | C18: Publisher, source type, URL, retrieval date and limitations for each source.
A19: Data Gaps | C19: Certificate requirements, material conflicts, missing fields and an editable verification status.
A21: READ BEFORE USING THE DATA
A22: Not certificate-verified. This is a researched public-source compilation, not an official builder, flag or class register. Current registry, radio, tonnage and class documents take precedence for operational use.
A24: Selection policy: prefer current Oceanco overall dimensions; retain database dimensions separately. Prefer builder GT when explicitly published, otherwise record database GT as a working value. “Overall beam” is not automatically moulded breadth.
A26: Identity and history: IMO is the linking key. Names, MMSI, call sign and flag are observations at retrieval and may change or be stale. Reused names do not identify the same hull. No live positions or voyage tracking are included.
A28: Missing data: blank numeric fields and “Not verified” do not mean zero, absent or not fitted. No live AIS draught was used as design/max draught. Public guest counts are not certified maximum persons on board.
A30: Units: length / beam / draft in metres; speeds in knots; range in nautical miles; deadweight in metric tonnes. GT is a dimensionless tonnage measure derived from enclosed volume, not the vessel's weight.
A32: Priority checks: Draak's post-rebuild tonnage; DreAMBoat's 4,550 / 4,525GT difference; AQuiJo's tonnage/length variants; Seven Seas' conflicting database dimensions/year; Koru's published length/beam differences.
A34: Update method: match by IMO; add each new observation and date to Field Evidence; keep previous observations; obtain a primary or statutory document to settle conflicts; then update the preferred value and its source. Do not overwrite unresolved alternatives.
A36: Version 1.1: external audit on 25 Sep 2026. Corrections to Y709 (GT), Y712 (naval architecture, interior), Y716 (former names); refit years added for Y714 and Y717; three data gaps added. See the Audit sheet.
A37: Evidence observations / source records | G37: =COUNTA('Field Evidence'!D5:D459) -> 455 | H37: =COUNTA(Sources!A5:A89) -> 85
A39: Method references: IMO_ID and IMO_GT in Sources. Research snapshot, not a guarantee of present registration or configuration.

Sheet Vessel Register
A1: OCEANCO | Y700 VESSEL REGISTER
A2: 22 identified vessels • research snapshot 25 September 2026 • one record per IMO • public-source working data, not certificate-verified
A4: Yard ID | B4: Published vessel name | C4: Former names / aliases | D4: Delivered (year) | E4: Vessel type | F4: IMO | G4: MMSI | H4: Call sign | I4: Published flag | J4: Preferred LOA (m) | K4: Preferred beam (m) | L4: Working GT | M4: LOA / beam basis | N4: GT basis / qualification | O4: Identity qualification | P4: Dimensions / name notes | Q4: Builder URL | R4: Database URL | S4: Identity supplement URL | T4: Checked on
A5: Y701 | B5: Batello | C5: Amevi; Aalto | D5: 2007 | E5: Motor yacht | F5: 1009118 | G5: 538070869 | H5: V7YZ2 | I5: Marshall Islands | J5: 80 | K5: 14.2 | L5: 2310 | M5: Oceanco current fleet page (published overall dimensions) | N5: VesselFinder static particulars | O5: Published database identity; current registry/radio licence not inspected. | P5: Builder beam 14.2m vs database 12.0m. Broker top-speed values conflict (19/20kn). | Q5: https://www.oceancoyacht.com/fleet/batello/ | R5: https://www.vesselfinder.com/vessels/details/1009118 | T5: 46290
A6: Y702 | B6: Alfa Nero | C6: None identified | D6: 2007 | E6: Motor yacht | F6: 1009376 | G6: 249108000 | H6: 9HA6112 | I6: Malta | J6: 82 | K6: 14.2 | L6: 2159 | M6: Oceanco current fleet page (published overall dimensions) | N6: VesselFinder static particulars | O6: Published database identity; current registry/radio licence not inspected. | P6: Builder LOA 82m vs database 81.27m. Broker draft is not a certified maximum draft. | Q6: https://www.oceancoyacht.com/fleet/alfa-nero/ | R6: https://www.vesselfinder.com/vessels/details/1009376 | T6: 46290
A7: Y703 | B7: Wheels | C7: Anastasia | D7: 2008 | E7: Motor yacht | F7: 1009388 | G7: 215279000 | H7: 9HA5036 | I7: Malta | J7: 75.5 | K7: 13.5 | L7: 1991 | M7: Oceanco current fleet page (published overall dimensions) | N7: VesselFinder static particulars | O7: Published database identity; current registry/radio licence not inspected. | P7: Builder beam 13.5m; broker 13.49m; database 13.38m. | Q7: https://www.oceancoyacht.com/fleet/wheels/ | R7: https://www.vesselfinder.com/vessels/details/1009388 | T7: 46290
A8: Y704 | B8: Vibrant Curiosity | C8: None identified | D8: 2009 | E8: Motor yacht | F8: 1010002 | G8: 248983000 | H8: 9HA4898 | I8: Malta | J8: 85.5 | K8: 14.2 | L8: 2822 | M8: Oceanco current fleet page (published overall dimensions) | N8: VesselFinder static particulars | O8: Call sign supplemented from MarineTraffic; use IMO match, not legacy MMSI embedded in URL. | P8: Builder 85.5 x 14.2m; database 85.43 x 13.8m. | Q8: https://www.oceancoyacht.com/fleet/vibrant-curiosity/ | R8: https://www.vesselfinder.com/vessels/details/1010002 | S8: https://www.marinetraffic.com/es/ais/details/ships/shipid%3A194250/mmsi%3A235068366/imo%3A1010002/vessel%3AVIBRANT%20CURIOSITY | T8: 46290
A9: Y705 | B9: Sunrays | C9: None identified | D9: 2010 | E9: Motor yacht | F9: 1010351 | G9: 319015100 | H9: ZGAF2 | I9: Cayman Islands | J9: 85.5 | K9: 14.2 | L9: 2867 | M9: Oceanco current fleet page (published overall dimensions) | N9: VesselFinder static particulars | O9: Published database identity; current registry/radio licence not inspected. | P9: Builder beam 14.2m; Edmiston 13.8m; database 14.24m. | Q9: https://www.oceancoyacht.com/fleet/sunrays/ | R9: https://www.vesselfinder.com/vessels/details/1010351 | T9: 46290
A10: Y706 | B10: Man of Steel | C10: Seven Seas (86m) | D10: 2010 | E10: Motor yacht | F10: 1010777 | G10: 319729000 | H10: ZGAZ5 | I10: Cayman Islands | J10: 86 | K10: 14.2 | L10: 2658 | M10: Oceanco fleet LOA; VF beam | N10: VesselFinder static particulars | O10: Published database identity; current registry/radio licence not inspected. | P10: LOA/year from builder fleet page; 14.2m beam from database because detail page unavailable. | Q10: https://www.oceancoyacht.com/fleet/?pag=2 | R10: https://www.vesselfinder.com/vessels/details/1010777 | T10: 46290
A11: Y707 | B11: Nirvana | C11: AIS name: MY NIRVANA | D11: 2012 | E11: Motor yacht | F11: 1011202 | G11: 533132675 | H11: 9M3187 | I11: Malaysia (AIS) | J11: 88.5 | K11: 14.2 | L11: 2786 | M11: Oceanco current fleet page (published overall dimensions) | N11: VesselFinder static particulars | O11: AIS header says Malaysia; static flag field says Unknown. Current registry certificate not checked. | P11: Builder LOA 88.5m; database 88.39m. | Q11: https://www.oceancoyacht.com/fleet/nirvana/ | R11: https://www.vesselfinder.com/vessels/details/1011202 | T11: 46290
A12: Y708 | B12: Amore Vero | C12: St. Princess Olga | D12: 2013 | E12: Motor yacht | F12: 1011757 | G12: 533132553 | H12: 9M3050 | I12: Malaysia (AIS) | J12: 85.6 | K12: 14.2 | L12: 2744 | M12: Oceanco current fleet page (published overall dimensions) | N12: VesselFinder static particulars | O12: AIS header says Malaysia; static flag field says Unknown. Current registry certificate not checked. | P12: Builder LOA 85.6m vs database 88.39m; do not merge these dimensions. | Q12: https://www.oceancoyacht.com/fleet/amore-vero/ | R12: https://www.vesselfinder.com/vessels/details/1011757 | T12: 46290
A13: Y709 | B13: Draak | C13: Equanimity; Tranquility | D13: 2014 | E13: Motor / expedition yacht | F13: 1012086 | G13: 319059800 | H13: ZGDQ | I13: Cayman Islands | J13: 92.9 | K13: 14.5 | L13: 2951 | M13: Oceanco current fleet page (published overall dimensions) | N13: Y.CO / SuperYacht Times / Wikipedia published GT — post-June 2026 rebuild remeasurement not verified | O13: Published database identity; current registry/radio licence not inspected. | P13: Builder 92.9 x 14.5m after June 2026 rebuild. Database 91.5 x 14.6m / 2894GT may be pre-refit; obtain new ITC. Audit 25 Sep 2026: 2951GT (majority published figure) replaces VesselFinder 2894GT as working value. | Q13: https://www.oceancoyacht.com/fleet/draak/ | R13: https://www.vesselfinder.com/vessels/details/1012086 | T13: 46290
A14: Y710 | B14: Samsara | C14: Infinity (89m); Cloud 9 | D14: 2015 | E14: Motor yacht | F14: 1012177 | G14: 319068100 | H14: ZGEC5 | I14: Cayman Islands | J14: 89 | K14: 14.2 | L14: 2914 | M14: Oceanco current fleet page (published overall dimensions) | N14: VesselFinder static particulars | O14: MMSI/call/flag supplemented from MagicPort; VesselFinder AIS identity header incomplete. | P14: Builder beam 14.2m vs database 14.0m. Distinct from 117m Infinity. | Q14: https://www.oceancoyacht.com/fleet/samsara/ | R14: https://www.vesselfinder.com/vessels/details/1012177 | S14: https://magicport.ai/vessels/pleasure-craft/samsara-mmsi-319068100 | T14: 46290
A15: Y711 | B15: AQuiJo | C15: None identified | D15: 2016 | E15: Sailing yacht / ketch | F15: 1012529 | G15: 319085900 | H15: ZGFC8 | I15: Cayman Islands | J15: 85 | K15: 14.5 | L15: 1540 | M15: Oceanco current fleet page (published overall dimensions) | N15: VesselFinder static particulars — broker states 1,538GT | O15: VesselFinder showed an AIS report approximately 303 days old. Registration freshness not confirmed. | P15: Builder LOA 85m vs broker 86m. Database 1540GT vs Y.CO 1538GT; both unverified. | Q15: https://www.oceancoyacht.com/fleet/aquijo/ | R15: https://www.vesselfinder.com/vessels/details/1012529 | T15: 46290
A16: Y712 | B16: Black Pearl | C16: None identified | D16: 2018 | E16: Sailing yacht / DynaRig | F16: 1012490 | G16: 319113100 | H16: ZGGH7 | I16: Cayman Islands | J16: 106.7 | K16: 15 | L16: 2864 | M16: Oceanco current fleet page (published overall dimensions) | N16: VesselFinder static particulars | O16: Published database identity; current registry/radio licence not inspected. | P16: Builder 106.7m vs database 105m. Builder 2018 is delivery, not launch. 30kn is sailing, not engine speed. | Q16: https://www.oceancoyacht.com/fleet/black-pearl/ | R16: https://www.vesselfinder.com/vessels/details/1012490 | T16: 46290
A17: Y714 | B17: KAOS | C17: Jubilee | D17: 2017 | E17: Motor yacht | F17: 1012610 | G17: 339302000 | H17: 6YVQ2 | I17: Jamaica | J17: 110 | K17: 16.4 | L17: 4523 | M17: Oceanco current fleet page (published overall dimensions) | N17: VesselFinder static particulars | O17: Published database identity; current registry/radio licence not inspected. | P17: Builder LOA 110m vs database 105m; beam 16.4m vs 16m. Interior credit is original build. | Q17: https://www.oceancoyacht.com/fleet/kaos/ | R17: https://www.vesselfinder.com/vessels/details/1012610 | T17: 46290
A18: Y715 | B18: Barbara | C18: None identified | D18: 2017 | E18: Motor yacht | F18: 1012725 | G18: 319104200 | H18: ZGFN2 | I18: Cayman Islands | J18: 88.5 | K18: 14.5 | L18: 2984 | M18: Oceanco current fleet page (published overall dimensions) | N18: VesselFinder static particulars | O18: Published database identity; current registry/radio licence not inspected. | P18: Builder beam 14.5m; designer as-built 14.2m; database 14.45m. Supplemental data is 2017 configuration. | Q18: https://www.oceancoyacht.com/fleet/barbara/ | R18: https://www.vesselfinder.com/vessels/details/1012725 | T18: 46290
A19: Y716 | B19: SHODAN | C19: DreAMBoat (90m); DREAMBOAT 1; Project Yasmin | D19: 2019 | E19: Motor yacht | F19: 1012919 | G19: 319151300 | H19: ZGIC7 | I19: Cayman Islands | J19: 90 | K19: 14.2 | L19: 2946 | M19: Oceanco current fleet page (published overall dimensions) | N19: VesselFinder static particulars | O19: Published database identity; current registry/radio licence not inspected. | P19: Former 90m DreAMBoat; separate IMO and yard number from 111m DreAMBoat (Y726). | Q19: https://www.oceancoyacht.com/fleet/shodan/ | R19: https://www.vesselfinder.com/vessels/details/1012919 | T19: 46290
A20: Y717 | B20: LUNA | C20: Dar | D20: 2018 | E20: Motor yacht | F20: 1013066 | G20: 319133300 | H20: ZGHL5 | I20: Cayman Islands | J20: 90 | K20: 14.2 | L20: 2926 | M20: Oceanco current fleet page (published overall dimensions) | N20: VesselFinder static particulars | O20: Published database identity; current registry/radio licence not inspected. | P20: Builder rounds LOA to 90m; Y.CO/database give 90.13m. Database beam 13.8m vs builder 14.2m. | Q20: https://www.oceancoyacht.com/fleet/luna/ | R20: https://www.vesselfinder.com/vessels/details/1013066 | T20: 46290
A21: Y718 | B21: Bravo Eugenia | C21: None identified | D21: 2018 | E21: Motor yacht / hybrid | F21: 1012921 | G21: 319156800 | H21: ZGIL4 | I21: Cayman Islands | J21: 109 | K21: 16.3 | L21: 3418 | M21: Oceanco current fleet page (published overall dimensions) | N21: VesselFinder static particulars | O21: Published database identity; current registry/radio licence not inspected. | P21: Builder beam 16.3m vs database 16m. | Q21: https://www.oceancoyacht.com/fleet/bravo-eugenia/ | R21: https://www.vesselfinder.com/vessels/details/1012921 | T21: 46290
A22: Y719 | B22: Infinity | C22: None identified | D22: 2022 | E22: Motor yacht | F22: 9817896 | G22: 319208000 | H22: ZGKZ3 | I22: Cayman Islands | J22: 117 | K22: 16.5 | L22: 4978 | M22: Oceanco current fleet page (published overall dimensions) | N22: VesselFinder static particulars | O22: Published database identity; current registry/radio licence not inspected. | P22: Builder beam 16.5m vs database 17m. Distinct from original 89m Infinity (now Samsara). | Q22: https://www.oceancoyacht.com/fleet/infinity/ | R22: https://www.vesselfinder.com/vessels/details/9817896 | T22: 46290
A23: Y720 | B23: Seven Seas | C23: None identified | D23: 2023 | E23: Motor yacht | F23: 9840178 | G23: 319225300 | H23: ZGQC2 | I23: Cayman Islands | J23: 109 | K23: 16 | L23: 4444 | M23: Oceanco current fleet page (published overall dimensions) | N23: VesselFinder static particulars | O23: Published database identity; current registry/radio licence not inspected. | P23: Database static 125 x 17m / 2022 is quarantined. Builder 109 x 16m / 2023; database AIS dimensions also 109 x 16m. | Q23: https://www.oceancoyacht.com/fleet/seven-seas/ | R23: https://www.vesselfinder.com/vessels/details/9840178 | T23: 46290
A24: Y721 | B24: Koru | C24: None identified | D24: 2023 | E24: Sailing yacht / schooner | F24: 9857298 | G24: 319225400 | H24: ZGQC5 | I24: Cayman Islands | J24: 125 | K24: 17.2 | L24: 3493 | M24: Oceanco current fleet page (published overall dimensions) | N24: VesselFinder static particulars | O24: Published database identity; current registry/radio licence not inspected. | P24: Builder 125 x 17.2m. Lateral title says 125m, body 127 x 16m. Database beam 17m. | Q24: https://www.oceancoyacht.com/fleet/koru/ | R24: https://www.vesselfinder.com/vessels/details/9857298 | T24: 46290
A25: Y722 | B25: Leviathan | C25: None identified | D25: 2025 | E25: Motor yacht / diesel-electric | F25: 9921491 | G25: 319324100 | H25: ZGUZ3 | I25: Cayman Islands | J25: 111 | K25: 17.8 | L25: 4970 | M25: Oceanco current fleet page (published overall dimensions) | N25: Oceanco / Lateral publication | O25: Published database identity; current registry/radio licence not inspected. | P25: Builder/Lateral 111 x 17.8m; database 110 x 15m. Builder and database agree 4970GT. | Q25: https://www.oceancoyacht.com/fleet/leviathan/ | R25: https://www.vesselfinder.com/vessels/details/9921491 | T25: 46290
A26: Y726 | B26: DreAMBoat | C26: Database build alias: ALBLASSERDAM726 | D26: 2025 | E26: Motor yacht | F26: 9967093 | G26: 319305800 | H26: ZGRP2 | I26: Cayman Islands | J26: 111 | K26: 16 | L26: 4550 | M26: Oceanco current fleet page (published overall dimensions) | N26: Oceanco / Lateral publication — database states 4,525GT | O26: Published database identity; current registry/radio licence not inspected. | P26: Builder/Lateral 4550GT vs database 4525GT; builder LOA 111m vs database 110m. Not SHODAN/Y716. | Q26: https://www.oceancoyacht.com/fleet/dreamboat/ | R26: https://www.vesselfinder.com/vessels/details/9967093 | T26: 46290

Sheet Technical Particulars
A1: TECHNICAL PARTICULARS | PUBLICLY SUPPORTED FIELDS
A2: Blank numeric cells / 'Not verified' mean no sufficiently supported value was captured • field-level sources and historical/current basis are in Field Evidence
A4: Yard ID | B4: Vessel | C4: Draft (m) [published] | D4: Hull | E4: Superstructure | F4: Naval architecture / engineering | G4: Exterior design | H4: Interior design | I4: Main machinery | J4: Propulsion / energy | K4: Cruise (kn) | L4: Max motor (kn) | M4: Max sail (kn) | N4: Range (nm) | O4: Guests [published] | P4: Guest cabins | Q4: Crew [published] | R4: Class society [published] | S4: Refit/rebuild identified | T4: Selected features | U4: Source IDs | V4: Source URLs | W4: Qualification
A5: Y701 | B5: Batello | D5: Steel | E5: Not verified | F5: Not verified | G5: Nuvolari Lenard | H5: Alberto Pinto (original) | I5: Not verified | J5: Not verified | K5: 14 | L5: 20 | O5: 12 | P5: 9 | Q5: 26 | R5: Not verified | S5: 2025 | T5: Retractable zero-speed stabilisers; interior refit by FM Architettura | U5: B701; Y701 | V5: https://www.oceancoyacht.com/fleet/batello/ https://iyc.com/charter/batello/ | W5: Published accommodation is not a certified persons-on-board limit. Draft is not assumed to be maximum/design draft. Range speed/load condition is unverified. Broker maximum speed conflict: 19/20kn.
A6: Y702 | B6: Alfa Nero | C6: 3.9 | D6: Steel | E6: Not verified | F6: Not verified | G6: Nuvolari Lenard | H6: Alberto Pinto | I6: 2 x MTU 4,680 hp (broker notation) | J6: Not verified | K6: 15 | L6: 20 | N6: 5500 | O6: 12 | P6: 6 | Q6: 28 | R6: Lloyd's Register | S6: 2024 | T6: 6 guest staterooms plus 1 staff suite; stabilisation at anchor and underway | U6: B702; FR702 | V6: https://www.oceancoyacht.com/fleet/alfa-nero/ https://www.fraseryachts.com/en/yacht-for-sale/alfa-nero/ | W6: Published accommodation is not a certified persons-on-board limit. Draft is not assumed to be maximum/design draft. Range speed/load condition is unverified.
A7: Y703 | B7: Wheels | C7: 3.86 | D7: Steel | E7: Not verified | F7: Not verified | G7: Sam Sorgiovanni | H7: Sam Sorgiovanni | I7: 2 x MTU 3,655 hp (broker notation) | J7: Not verified | K7: 15 | L7: 18 | N7: 4500 | O7: 12 | P7: 6 | Q7: 21 | R7: Lloyd's Register | S7: 2024 | T7: Stabilisation at anchor and underway | U7: B703; FR703 | V7: https://www.oceancoyacht.com/fleet/wheels/ https://www.fraseryachts.com/en/yacht-for-charter/wheels/ | W7: Published accommodation is not a certified persons-on-board limit. Draft is not assumed to be maximum/design draft. Range speed/load condition is unverified.
A8: Y704 | B8: Vibrant Curiosity | D8: Not verified | E8: Not verified | F8: Not verified | G8: Nuvolari Lenard | H8: Nuvolari Lenard | I8: Not verified | J8: Not verified | N8: 5500 | R8: Not verified | T8: Not verified | U8: B704 | V8: https://www.oceancoyacht.com/fleet/vibrant-curiosity/ | W8: Published accommodation is not a certified persons-on-board limit. Draft is not assumed to be maximum/design draft. Range speed/load condition is unverified.
A9: Y705 | B9: Sunrays | C9: 3.95 | D9: Steel | E9: Aluminium | F9: Azure | G9: Björn Johansson | H9: Terence Disdale | I9: Not verified | J9: Not verified | K9: 14 | O9: 12 | P9: 8 | Q9: 29 | R9: Not verified | S9: 2025 | T9: Not verified | U9: B705; ED705 | V9: https://www.oceancoyacht.com/fleet/sunrays/ https://www.edmiston.com/50/sunrays-yacht-charter/ | W9: Published accommodation is not a certified persons-on-board limit. Draft is not assumed to be maximum/design draft. Range speed/load condition is unverified.
A10: Y706 | B10: Man of Steel | D10: Steel | E10: Not verified | F10: Azure | G10: Nuvolari Lenard | H10: Not verified | I10: Not verified | J10: Not verified | R10: Not verified | T10: Not verified | U10: CW706 | V10: https://www.charterworld.com/index.html?charter=motor-yacht-y-5937&sub=yacht-charter | W10: Published accommodation is not a certified persons-on-board limit. Draft is not assumed to be maximum/design draft. Range speed/load condition is unverified.
A11: Y707 | B11: Nirvana | D11: Not verified | E11: Not verified | F11: Not verified | G11: Sam Sorgiovanni | H11: Sam Sorgiovanni | I11: Not verified | J11: Not verified | R11: Not verified | T11: Not verified | U11: B707 | V11: https://www.oceancoyacht.com/fleet/nirvana/ | W11: Published accommodation is not a certified persons-on-board limit. Draft is not assumed to be maximum/design draft. Range speed/load condition is unverified.
A12: Y708 | B12: Amore Vero | D12: Not verified | E12: Not verified | F12: Not verified | G12: Lobanov Design | H12: Alberto Pinto | I12: Not verified | J12: Not verified | R12: Not verified | T12: Not verified | U12: B708 | V12: https://www.oceancoyacht.com/fleet/amore-vero/ | W12: Published accommodation is not a certified persons-on-board limit. Draft is not assumed to be maximum/design draft. Range speed/load condition is unverified.
A13: Y709 | B13: Draak | D13: Not verified | E13: Not verified | F13: Not verified | G13: Not verified | H13: Not verified | I13: Not verified | J13: Not verified | R13: Not verified | S13: 2026 | T13: Dive centre; medical room; hyperbaric chamber; scientific work facilities | U13: DRAAK26 | V13: https://www.oceancoyacht.com/leviathan-and-draak-at-the-2026-monaco-yacht-show/ | W13: Published accommodation is not a certified persons-on-board limit. Draft is not assumed to be maximum/design draft. Range speed/load condition is unverified. Original machinery/accommodation intentionally not carried forward across 2026 rebuild.
A14: Y710 | B14: Samsara | D14: Not verified | E14: Not verified | F14: Not verified | G14: Espen Øino | H14: Sinot; David Kleinberg | I14: Not verified | J14: Not verified | R14: Not verified | T14: Not verified | U14: B710 | V14: https://www.oceancoyacht.com/fleet/samsara/ | W14: Published accommodation is not a certified persons-on-board limit. Draft is not assumed to be maximum/design draft. Range speed/load condition is unverified.
A15: Y711 | B15: AQuiJo | C15: 5.3 | D15: Not verified | E15: Not verified | F15: Not verified | G15: Tripp Design | H15: Dölker + Voges | I15: Not verified | J15: Not verified | O15: 12 | P15: 7 | Q15: 17 | R15: Not verified | T15: Not verified | U15: B711; YC711 | V15: https://www.oceancoyacht.com/fleet/aquijo/ https://y.co/yacht/aquijo | W15: Published accommodation is not a certified persons-on-board limit. Draft is not assumed to be maximum/design draft. Range speed/load condition is unverified. Broker also publishes 17kn maximum without identifying propulsion mode; see Field Evidence.
A16: Y712 | B16: Black Pearl | D16: Not verified | E16: Not verified | F16: Oceanco; Dykstra Naval Architects (hull & DynaRig); Lateral / BMT (engineering) | G16: Ken Freivokh; Nuvolari Lenard | H16: Ken Freivokh; Nuvolari Lenard; Villate | I16: Not verified | J16: Hybrid propulsion with sailing-energy integration | M16: 30 | R16: Not verified | T16: Not verified | U16: B712; LAT712; DYK712 | V16: https://www.oceancoyacht.com/fleet/black-pearl/ https://www.lateral.engineering/projects/black-pearl/ https://www.dykstra-na.nl/designs/black-pearl/ | W16: Published accommodation is not a certified persons-on-board limit. Draft is not assumed to be maximum/design draft. Range speed/load condition is unverified.
A17: Y714 | B17: KAOS | D17: Not verified | E17: Not verified | F17: Azure (hull); Lateral / Oceanco (engineering) | G17: Lobanov Design | H17: Sam Sorgiovanni (original); Reymond Langton Design (2020 Lürssen refit) | I17: Not verified | J17: Not verified | O17: 30 | R17: Not verified | S17: 2020 | T17: Not verified | U17: B714; LAT714; RL714 | V17: https://www.oceancoyacht.com/fleet/kaos/ https://www.lateral.engineering/projects/kaos/ https://www.reymondlangtondesign.com/110m-motor-yacht-kaos-delivered-after-major-lurssen-refit/ | W17: Published accommodation is not a certified persons-on-board limit. Draft is not assumed to be maximum/design draft. Range speed/load condition is unverified.
A18: Y715 | B18: Barbara | C18: 3.95 | D18: Steel | E18: Aluminium | F18: Not verified | G18: Sam Sorgiovanni | H18: Sam Sorgiovanni | I18: Not verified | J18: Not verified | K18: 16 | L18: 19 | O18: 12 | Q18: 27 | R18: Not verified | T18: Not verified | U18: B715; Y715 | V18: https://www.oceancoyacht.com/fleet/barbara/ https://www.sorgiovanniinteriors.com.au/barbara/ | W18: Published accommodation is not a certified persons-on-board limit. Draft is not assumed to be maximum/design draft. Range speed/load condition is unverified. Designer data is as built in 2017.
A19: Y716 | B19: SHODAN | D19: Not verified | E19: Not verified | F19: Not verified | G19: Espen Øino | H19: Terence Disdale | I19: Not verified | J19: Not verified | O19: 23 | R19: Not verified | T19: Not verified | U19: B716 | V19: https://www.oceancoyacht.com/fleet/shodan/ | W19: Published accommodation is not a certified persons-on-board limit. Draft is not assumed to be maximum/design draft. Range speed/load condition is unverified.
A20: Y717 | B20: LUNA | C20: 3.95 | D20: Not verified | E20: Not verified | F20: Not verified | G20: DeBasto Designs | H20: Nuvolari Lenard | I20: Not verified | J20: Not verified | L20: 20 | O20: 12 | P20: 7 | Q20: 30 | R20: Not verified | S20: 2024 | T20: Not verified | U20: B717; YC717 | V20: https://www.oceancoyacht.com/fleet/luna/ https://y.co/yacht/luna | W20: Published accommodation is not a certified persons-on-board limit. Draft is not assumed to be maximum/design draft. Range speed/load condition is unverified.
A21: Y718 | B21: Bravo Eugenia | D21: Not verified | E21: Not verified | F21: Lateral; Oceanco | G21: Nuvolari Lenard | H21: Reymond Langton | I21: 2 x 1,440 kW MTU | J21: Hybrid LIFE platform; batteries and waste-heat recovery | R21: Not verified | T21: Not verified | U21: B718; LAT718 | V21: https://www.oceancoyacht.com/fleet/bravo-eugenia/ https://www.lateral.engineering/projects/bravo/ | W21: Published accommodation is not a certified persons-on-board limit. Draft is not assumed to be maximum/design draft. Range speed/load condition is unverified.
A22: Y719 | B22: Infinity | D22: Not verified | E22: Not verified | F22: Lateral; Oceanco | G22: Espen Øino | H22: Sinot; David Kleinberg | I22: Not verified | J22: Not verified | O22: 16 | R22: Not verified | T22: Not verified | U22: B719; LAT719 | V22: https://www.oceancoyacht.com/fleet/infinity/ https://www.lateral.engineering/projects/Inifinity-117m/ | W22: Published accommodation is not a certified persons-on-board limit. Draft is not assumed to be maximum/design draft. Range speed/load condition is unverified.
A23: Y720 | B23: Seven Seas | D23: Not verified | E23: Not verified | F23: Lateral; Oceanco | G23: Sinot Yacht Architecture & Design | H23: Sinot; Molly Isaksen (decoration) | I23: Not verified | J23: Not verified | L23: 20 | R23: Not verified | T23: Not verified | U23: B720; LAT720 | V23: https://www.oceancoyacht.com/fleet/seven-seas/ https://www.lateral.engineering/projects/Seven-Seas-357ft/ | W23: Published accommodation is not a certified persons-on-board limit. Draft is not assumed to be maximum/design draft. Range speed/load condition is unverified.
A24: Y721 | B24: Koru | D24: Not verified | E24: Not verified | F24: Lateral; Dykstra Naval Architects | G24: Dykstra Naval Architects | H24: Tino Zervudachi & Associés | I24: Not verified | J24: Not verified | R24: Not verified | T24: Not verified | U24: B721 | V24: https://www.oceancoyacht.com/fleet/koru/ | W24: Published accommodation is not a certified persons-on-board limit. Draft is not assumed to be maximum/design draft. Range speed/load condition is unverified.
A25: Y722 | B25: Leviathan | D25: Not verified | E25: Not verified | F25: Lateral; Oceanco | G25: Oceanco | H25: Mark Berryman | I25: Not verified | J25: Diesel-electric | R25: Not verified | T25: Scientific and dive operations; medical facilities | U25: B722; LAT722 | V25: https://www.oceancoyacht.com/fleet/leviathan/ https://www.lateral.engineering/projects/leviathan/ | W25: Published accommodation is not a certified persons-on-board limit. Draft is not assumed to be maximum/design draft. Range speed/load condition is unverified.
A26: Y726 | B26: DreAMBoat | D26: Not verified | E26: Not verified | F26: Lateral; Oceanco | G26: Espen Øino | H26: Mark Berryman | I26: Not verified | J26: Battery-supported energy / peak-load management | R26: Not verified | T26: Not verified | U26: B726; LAT726 | V26: https://www.oceancoyacht.com/fleet/dreamboat/ https://www.lateral.engineering/projects/y726-364ft/ | W26: Published accommodation is not a certified persons-on-board limit. Draft is not assumed to be maximum/design draft. Range speed/load condition is unverified.

Sheet Source Comparison
A1: SOURCE COMPARISON | DO NOT SILENTLY MERGE
A2: Deltas = preferred public value minus VesselFinder static value • differences identify review needs, not proof of error • blank database year was not separately recorded
A4: Yard ID | B4: Vessel | C4: Preferred LOA (m) | D4: VF static LOA (m) | E4: Δ LOA (m) | F4: Preferred beam (m) | G4: VF static beam (m) | H4: Δ beam (m) | I4: Working GT | J4: VF static GT | K4: Δ GT | L4: Builder delivery year | M4: VF build year [checked] | N4: Year difference | O4: Review flag | P4: Key interpretation | Q4: Source URLs
A5: Y701 | B5: Batello | C5: 80 | D5: 80 | E5: =ROUND(C5-D5,2) -> 0 | F5: 14.2 | G5: 12 | H5: =ROUND(F5-G5,2) -> 2.2 | I5: 2310 | J5: 2310 | K5: =I5-J5 -> 0 | L5: 2007 | N5: =IF(M5="","",L5-M5) | O5: =IF(OR(E5<>0,H5<>0,K5<>0,AND(M5<>"",L5<>M5)),"REVIEW","ALIGNED") -> REVIEW | P5: Builder beam 14.2m vs database 12.0m. Broker top-speed values conflict (19/20kn). | Q5: https://www.oceancoyacht.com/fleet/batello/ https://www.vesselfinder.com/vessels/details/1009118
A6: Y702 | B6: Alfa Nero | C6: 82 | D6: 81.27 | E6: =ROUND(C6-D6,2) -> 0.73 | F6: 14.2 | G6: 14.24 | H6: =ROUND(F6-G6,2) -> -0.04 | I6: 2159 | J6: 2159 | K6: =I6-J6 -> 0 | L6: 2007 | N6: =IF(M6="","",L6-M6) | O6: =IF(OR(E6<>0,H6<>0,K6<>0,AND(M6<>"",L6<>M6)),"REVIEW","ALIGNED") -> REVIEW | P6: Builder LOA 82m vs database 81.27m. Broker draft is not a certified maximum draft. | Q6: https://www.oceancoyacht.com/fleet/alfa-nero/ https://www.vesselfinder.com/vessels/details/1009376
A7: Y703 | B7: Wheels | C7: 75.5 | D7: 75.5 | E7: =ROUND(C7-D7,2) -> 0 | F7: 13.5 | G7: 13.38 | H7: =ROUND(F7-G7,2) -> 0.12 | I7: 1991 | J7: 1991 | K7: =I7-J7 -> 0 | L7: 2008 | N7: =IF(M7="","",L7-M7) | O7: =IF(OR(E7<>0,H7<>0,K7<>0,AND(M7<>"",L7<>M7)),"REVIEW","ALIGNED") -> REVIEW | P7: Builder beam 13.5m; broker 13.49m; database 13.38m. | Q7: https://www.oceancoyacht.com/fleet/wheels/ https://www.vesselfinder.com/vessels/details/1009388
A8: Y704 | B8: Vibrant Curiosity | C8: 85.5 | D8: 85.43 | E8: =ROUND(C8-D8,2) -> 0.07 | F8: 14.2 | G8: 13.8 | H8: =ROUND(F8-G8,2) -> 0.4 | I8: 2822 | J8: 2822 | K8: =I8-J8 -> 0 | L8: 2009 | N8: =IF(M8="","",L8-M8) | O8: =IF(OR(E8<>0,H8<>0,K8<>0,AND(M8<>"",L8<>M8)),"REVIEW","ALIGNED") -> REVIEW | P8: Builder 85.5 x 14.2m; database 85.43 x 13.8m. | Q8: https://www.oceancoyacht.com/fleet/vibrant-curiosity/ https://www.vesselfinder.com/vessels/details/1010002
A9: Y705 | B9: Sunrays | C9: 85.5 | D9: 85.43 | E9: =ROUND(C9-D9,2) -> 0.07 | F9: 14.2 | G9: 14.24 | H9: =ROUND(F9-G9,2) -> -0.04 | I9: 2867 | J9: 2867 | K9: =I9-J9 -> 0 | L9: 2010 | N9: =IF(M9="","",L9-M9) | O9: =IF(OR(E9<>0,H9<>0,K9<>0,AND(M9<>"",L9<>M9)),"REVIEW","ALIGNED") -> REVIEW | P9: Builder beam 14.2m; Edmiston 13.8m; database 14.24m. | Q9: https://www.oceancoyacht.com/fleet/sunrays/ https://www.vesselfinder.com/vessels/details/1010351
A10: Y706 | B10: Man of Steel | C10: 86 | D10: 86.01 | E10: =ROUND(C10-D10,2) -> -0.01 | F10: 14.2 | G10: 14.2 | H10: =ROUND(F10-G10,2) -> 0 | I10: 2658 | J10: 2658 | K10: =I10-J10 -> 0 | L10: 2010 | N10: =IF(M10="","",L10-M10) | O10: =IF(OR(E10<>0,H10<>0,K10<>0,AND(M10<>"",L10<>M10)),"REVIEW","ALIGNED") -> REVIEW | P10: LOA/year from builder fleet page; 14.2m beam from database because detail page unavailable. | Q10: https://www.oceancoyacht.com/fleet/?pag=2 https://www.vesselfinder.com/vessels/details/1010777
A11: Y707 | B11: Nirvana | C11: 88.5 | D11: 88.39 | E11: =ROUND(C11-D11,2) -> 0.11 | F11: 14.2 | G11: 14.2 | H11: =ROUND(F11-G11,2) -> 0 | I11: 2786 | J11: 2786 | K11: =I11-J11 -> 0 | L11: 2012 | N11: =IF(M11="","",L11-M11) | O11: =IF(OR(E11<>0,H11<>0,K11<>0,AND(M11<>"",L11<>M11)),"REVIEW","ALIGNED") -> REVIEW | P11: Builder LOA 88.5m; database 88.39m. | Q11: https://www.oceancoyacht.com/fleet/nirvana/ https://www.vesselfinder.com/vessels/details/1011202
A12: Y708 | B12: Amore Vero | C12: 85.6 | D12: 88.39 | E12: =ROUND(C12-D12,2) -> -2.79 | F12: 14.2 | G12: 14.2 | H12: =ROUND(F12-G12,2) -> 0 | I12: 2744 | J12: 2744 | K12: =I12-J12 -> 0 | L12: 2013 | N12: =IF(M12="","",L12-M12) | O12: =IF(OR(E12<>0,H12<>0,K12<>0,AND(M12<>"",L12<>M12)),"REVIEW","ALIGNED") -> REVIEW | P12: Builder LOA 85.6m vs database 88.39m; do not merge these dimensions. | Q12: https://www.oceancoyacht.com/fleet/amore-vero/ https://www.vesselfinder.com/vessels/details/1011757
A13: Y709 | B13: Draak | C13: 92.9 | D13: 91.5 | E13: =ROUND(C13-D13,2) -> 1.4 | F13: 14.5 | G13: 14.6 | H13: =ROUND(F13-G13,2) -> -0.1 | I13: 2951 | J13: 2894 | K13: =I13-J13 -> 0 | L13: 2014 | N13: =IF(M13="","",L13-M13) | O13: =IF(OR(E13<>0,H13<>0,K13<>0,AND(M13<>"",L13<>M13)),"REVIEW","ALIGNED") -> REVIEW | P13: Builder 92.9 x 14.5m after June 2026 rebuild. Database 91.5 x 14.6m / 2894GT may be pre-refit; obtain new ITC. | Q13: https://www.oceancoyacht.com/fleet/draak/ https://www.vesselfinder.com/vessels/details/1012086
A14: Y710 | B14: Samsara | C14: 89 | D14: 89 | E14: =ROUND(C14-D14,2) -> 0 | F14: 14.2 | G14: 14 | H14: =ROUND(F14-G14,2) -> 0.2 | I14: 2914 | J14: 2914 | K14: =I14-J14 -> 0 | L14: 2015 | N14: =IF(M14="","",L14-M14) | O14: =IF(OR(E14<>0,H14<>0,K14<>0,AND(M14<>"",L14<>M14)),"REVIEW","ALIGNED") -> REVIEW | P14: Builder beam 14.2m vs database 14.0m. Distinct from 117m Infinity. | Q14: https://www.oceancoyacht.com/fleet/samsara/ https://www.vesselfinder.com/vessels/details/1012177
A15: Y711 | B15: AQuiJo | C15: 85 | D15: 85 | E15: =ROUND(C15-D15,2) -> 0 | F15: 14.5 | G15: 14.4 | H15: =ROUND(F15-G15,2) -> 0.1 | I15: 1540 | J15: 1540 | K15: =I15-J15 -> 0 | L15: 2016 | N15: =IF(M15="","",L15-M15) | O15: =IF(OR(E15<>0,H15<>0,K15<>0,AND(M15<>"",L15<>M15)),"REVIEW","ALIGNED") -> REVIEW | P15: Builder LOA 85m vs broker 86m. Database 1540GT vs Y.CO 1538GT; both unverified. | Q15: https://www.oceancoyacht.com/fleet/aquijo/ https://www.vesselfinder.com/vessels/details/1012529
A16: Y712 | B16: Black Pearl | C16: 106.7 | D16: 105 | E16: =ROUND(C16-D16,2) -> 1.7 | F16: 15 | G16: 14.98 | H16: =ROUND(F16-G16,2) -> 0.02 | I16: 2864 | J16: 2864 | K16: =I16-J16 -> 0 | L16: 2018 | M16: 2018 | N16: =IF(M16="","",L16-M16) -> 0 | O16: =IF(OR(E16<>0,H16<>0,K16<>0,AND(M16<>"",L16<>M16)),"REVIEW","ALIGNED") -> REVIEW | P16: Builder 106.7m vs database 105m. Builder 2018 is delivery, not launch. 30kn is sailing, not engine speed. | Q16: https://www.oceancoyacht.com/fleet/black-pearl/ https://www.vesselfinder.com/vessels/details/1012490
A17: Y714 | B17: KAOS | C17: 110 | D17: 105 | E17: =ROUND(C17-D17,2) -> 5 | F17: 16.4 | G17: 16 | H17: =ROUND(F17-G17,2) -> 0.4 | I17: 4523 | J17: 4523 | K17: =I17-J17 -> 0 | L17: 2017 | N17: =IF(M17="","",L17-M17) | O17: =IF(OR(E17<>0,H17<>0,K17<>0,AND(M17<>"",L17<>M17)),"REVIEW","ALIGNED") -> REVIEW | P17: Builder LOA 110m vs database 105m; beam 16.4m vs 16m. Interior credit is original build. | Q17: https://www.oceancoyacht.com/fleet/kaos/ https://www.vesselfinder.com/vessels/details/1012610
A18: Y715 | B18: Barbara | C18: 88.5 | D18: 88.5 | E18: =ROUND(C18-D18,2) -> 0 | F18: 14.5 | G18: 14.45 | H18: =ROUND(F18-G18,2) -> 0.05 | I18: 2984 | J18: 2984 | K18: =I18-J18 -> 0 | L18: 2017 | N18: =IF(M18="","",L18-M18) | O18: =IF(OR(E18<>0,H18<>0,K18<>0,AND(M18<>"",L18<>M18)),"REVIEW","ALIGNED") -> REVIEW | P18: Builder beam 14.5m; designer as-built 14.2m; database 14.45m. Supplemental data is 2017 configuration. | Q18: https://www.oceancoyacht.com/fleet/barbara/ https://www.vesselfinder.com/vessels/details/1012725
A19: Y716 | B19: SHODAN | C19: 90 | D19: 90 | E19: =ROUND(C19-D19,2) -> 0 | F19: 14.2 | G19: 14.2 | H19: =ROUND(F19-G19,2) -> 0 | I19: 2946 | J19: 2946 | K19: =I19-J19 -> 0 | L19: 2019 | N19: =IF(M19="","",L19-M19) | O19: =IF(OR(E19<>0,H19<>0,K19<>0,AND(M19<>"",L19<>M19)),"REVIEW","ALIGNED") -> ALIGNED | P19: Former 90m DreAMBoat; separate IMO and yard number from 111m DreAMBoat (Y726). | Q19: https://www.oceancoyacht.com/fleet/shodan/ https://www.vesselfinder.com/vessels/details/1012919
A20: Y717 | B20: LUNA | C20: 90 | D20: 90.13 | E20: =ROUND(C20-D20,2) -> -0.13 | F20: 14.2 | G20: 13.8 | H20: =ROUND(F20-G20,2) -> 0.4 | I20: 2926 | J20: 2926 | K20: =I20-J20 -> 0 | L20: 2018 | N20: =IF(M20="","",L20-M20) | O20: =IF(OR(E20<>0,H20<>0,K20<>0,AND(M20<>"",L20<>M20)),"REVIEW","ALIGNED") -> REVIEW | P20: Builder rounds LOA to 90m; Y.CO/database give 90.13m. Database beam 13.8m vs builder 14.2m. | Q20: https://www.oceancoyacht.com/fleet/luna/ https://www.vesselfinder.com/vessels/details/1013066
A21: Y718 | B21: Bravo Eugenia | C21: 109 | D21: 109 | E21: =ROUND(C21-D21,2) -> 0 | F21: 16.3 | G21: 16 | H21: =ROUND(F21-G21,2) -> 0.3 | I21: 3418 | J21: 3418 | K21: =I21-J21 -> 0 | L21: 2018 | N21: =IF(M21="","",L21-M21) | O21: =IF(OR(E21<>0,H21<>0,K21<>0,AND(M21<>"",L21<>M21)),"REVIEW","ALIGNED") -> REVIEW | P21: Builder beam 16.3m vs database 16m. | Q21: https://www.oceancoyacht.com/fleet/bravo-eugenia/ https://www.vesselfinder.com/vessels/details/1012921
A22: Y719 | B22: Infinity | C22: 117 | D22: 117 | E22: =ROUND(C22-D22,2) -> 0 | F22: 16.5 | G22: 17 | H22: =ROUND(F22-G22,2) -> -0.5 | I22: 4978 | J22: 4978 | K22: =I22-J22 -> 0 | L22: 2022 | M22: 2022 | N22: =IF(M22="","",L22-M22) -> 0 | O22: =IF(OR(E22<>0,H22<>0,K22<>0,AND(M22<>"",L22<>M22)),"REVIEW","ALIGNED") -> REVIEW | P22: Builder beam 16.5m vs database 17m. Distinct from original 89m Infinity (now Samsara). | Q22: https://www.oceancoyacht.com/fleet/infinity/ https://www.vesselfinder.com/vessels/details/9817896
A23: Y720 | B23: Seven Seas | C23: 109 | D23: 125 | E23: =ROUND(C23-D23,2) -> -16 | F23: 16 | G23: 17 | H23: =ROUND(F23-G23,2) -> -1 | I23: 4444 | J23: 4444 | K23: =I23-J23 -> 0 | L23: 2023 | M23: 2022 | N23: =IF(M23="","",L23-M23) -> 1 | O23: =IF(OR(E23<>0,H23<>0,K23<>0,AND(M23<>"",L23<>M23)),"REVIEW","ALIGNED") -> REVIEW | P23: Database static 125 x 17m / 2022 is quarantined. Builder 109 x 16m / 2023; database AIS dimensions also 109 x 16m. | Q23: https://www.oceancoyacht.com/fleet/seven-seas/ https://www.vesselfinder.com/vessels/details/9840178
A24: Y721 | B24: Koru | C24: 125 | D24: 125 | E24: =ROUND(C24-D24,2) -> 0 | F24: 17.2 | G24: 17 | H24: =ROUND(F24-G24,2) -> 0.2 | I24: 3493 | J24: 3493 | K24: =I24-J24 -> 0 | L24: 2023 | N24: =IF(M24="","",L24-M24) | O24: =IF(OR(E24<>0,H24<>0,K24<>0,AND(M24<>"",L24<>M24)),"REVIEW","ALIGNED") -> REVIEW | P24: Builder 125 x 17.2m. Lateral title says 125m, body 127 x 16m. Database beam 17m. | Q24: https://www.oceancoyacht.com/fleet/koru/ https://www.vesselfinder.com/vessels/details/9857298
A25: Y722 | B25: Leviathan | C25: 111 | D25: 110 | E25: =ROUND(C25-D25,2) -> 1 | F25: 17.8 | G25: 15 | H25: =ROUND(F25-G25,2) -> 2.8 | I25: 4970 | J25: 4970 | K25: =I25-J25 -> 0 | L25: 2025 | M25: 2025 | N25: =IF(M25="","",L25-M25) -> 0 | O25: =IF(OR(E25<>0,H25<>0,K25<>0,AND(M25<>"",L25<>M25)),"REVIEW","ALIGNED") -> REVIEW | P25: Builder/Lateral 111 x 17.8m; database 110 x 15m. Builder and database agree 4970GT. | Q25: https://www.oceancoyacht.com/fleet/leviathan/ https://www.vesselfinder.com/vessels/details/9921491
A26: Y726 | B26: DreAMBoat | C26: 111 | D26: 110 | E26: =ROUND(C26-D26,2) -> 1 | F26: 16 | G26: 16 | H26: =ROUND(F26-G26,2) -> 0 | I26: 4550 | J26: 4525 | K26: =I26-J26 -> 25 | L26: 2025 | M26: 2025 | N26: =IF(M26="","",L26-M26) -> 0 | O26: =IF(OR(E26<>0,H26<>0,K26<>0,AND(M26<>"",L26<>M26)),"REVIEW","ALIGNED") -> REVIEW | P26: Builder/Lateral 4550GT vs database 4525GT; builder LOA 111m vs database 110m. Not SHODAN/Y716. | Q26: https://www.oceancoyacht.com/fleet/dreamboat/ https://www.vesselfinder.com/vessels/details/9967093

Sheet Build Sequence
A1: BUILD SEQUENCE | Y701–Y726
A2: 22 mapped vessels; four numerical gaps retained explicitly • sorted by build code, not launch/delivery chronology • code-to-name sources are independent of current AIS identities
A4: Build code | B4: Mapped vessel | C4: IMO | D4: Delivered (year) | E4: Scope status | F4: Mapping evidence type | G4: Mapping source ID | H4: Mapping source URL | I4: Qualification
A5: Y701 | B5: Batello | C5: 1009118 | D5: 2007 | E5: Included — identified vessel | F5: Charter broker | G5: Y701 | H5: https://iyc.com/charter/batello/ | I5: Public project/IMO cross-reference; not a builder's certificate. Published top speed is inconsistent within page: 20kn specifications / 19kn narrative.
A6: Y702 | B6: Alfa Nero | C6: 1009376 | D6: 2007 | E6: Included — identified vessel | F6: Broker listing on marketplace | G6: Y702 | H6: https://www.yachtfocus.com/it/barca/2007-oceanco-y702-10043681/ | I6: Public project/IMO cross-reference; not a builder's certificate. Broker listing is used for yard-code cross-reference, not current statutory registration.
A7: Y703 | B7: Wheels | C7: 1009388 | D7: 2008 | E7: Included — identified vessel | F7: First-hand construction photograph | G7: Y703 | H7: https://www.shipspotting.com/photos/324611 | I7: Public project/IMO cross-reference; not a builder's certificate. Historical photo metadata; do not use its flag or radio identifiers as current.
A8: Y704 | B8: Vibrant Curiosity | C8: 1010002 | D8: 2009 | E8: Included — identified vessel | F8: First-hand construction photograph | G8: Y704 | H8: https://www.shipspotting.com/photos/458681 | I8: Public project/IMO cross-reference; not a builder's certificate. Historical photo metadata; current radio identifiers come from separate database sources.
A9: Y705 | B9: Sunrays | C9: 1010351 | D9: 2010 | E9: Included — identified vessel | F9: First-hand vessel photograph | G9: Y705 | H9: https://www.shipspotting.com/photos/2927955 | I9: Public project/IMO cross-reference; not a builder's certificate.
A10: Y706 | B10: Man of Steel | C10: 1010777 | D10: 2010 | E10: Included — identified vessel | F10: Supplier press release | G10: Y706 | H10: https://sandpeoplecommunication.wordpress.com/tag/tender/page/2/ | I10: Public project/IMO cross-reference; not a builder's certificate. Hodgdon tender-supplier release explicitly identifies Oceanco Y706 as M/Y Seven Seas.
A11: Y707 | B11: Nirvana | C11: 1011202 | D11: 2012 | E11: Included — identified vessel | F11: First-hand vessel photograph | G11: Y707 | H11: https://www.shipspotting.com/photos/1522215 | I11: Public project/IMO cross-reference; not a builder's certificate.
A12: Y708 | B12: Amore Vero | C12: 1011757 | D12: 2013 | E12: Included — identified vessel | F12: Broker vessel profile | G12: Y708 | H12: https://www.charterworld.com/index.html?charter=motor-yacht-y-6303&sub=yacht-charter | I12: Public project/IMO cross-reference; not a builder's certificate. Historical broker profile; not a current registration certificate.
A13: Y709 | B13: Draak | C13: 1012086 | D13: 2014 | E13: Included — identified vessel | F13: Refit contractor | G13: PRO | H13: https://www.proyacht.nl/custom-yacht-refit-portfolio/ | I13: Public project/IMO cross-reference; not a builder's certificate. Indexed portfolio identifies Y709 and Y719. Historical 91.5m Draak dimension is not the current builder LOA.
A14: Y710 | B14: Samsara | C14: 1012177 | D14: 2015 | E14: Included — identified vessel | F14: Project participant | G14: TC | H14: https://tech-consul.nl/projects | I14: Public project/IMO cross-reference; not a builder's certificate. Indexed project portfolio used for yard-code mapping only; rounded project lengths are not preferred dimensions.
A15: Y711 | B15: AQuiJo | C15: 1012529 | D15: 2016 | E15: Included — identified vessel | F15: Project participant | G15: TC | H15: https://tech-consul.nl/projects | I15: Public project/IMO cross-reference; not a builder's certificate. Indexed project portfolio used for yard-code mapping only; rounded project lengths are not preferred dimensions.
A16: Y712 | B16: Black Pearl | C16: 1012490 | D16: 2018 | E16: Included — identified vessel | F16: AIS database / historical | G16: Y712 | H16: https://www.myshiptracking.com/vessels/oceanco-y712-mmsi-244020868-imo-1012490 | I16: Public project/IMO cross-reference; not a builder's certificate. Historical construction identity only. Old MMSI is not used in the current register.
A17: Y713 | B17: Unmapped | E17: Unresolved numerical slot | F17: No verified mapping captured | I17: No vessel assigned in this workbook. Do not infer an unbuilt, cancelled or confidential project from the numbering gap.
A18: Y714 | B18: KAOS | C18: 1012610 | D18: 2017 | E18: Included — identified vessel | F18: Project participant | G18: TC | H18: https://tech-consul.nl/projects | I18: Public project/IMO cross-reference; not a builder's certificate. Indexed project portfolio used for yard-code mapping only; rounded project lengths are not preferred dimensions.
A19: Y715 | B19: Barbara | C19: 1012725 | D19: 2017 | E19: Included — identified vessel | F19: Designer | G19: Y715 | H19: https://www.sorgiovanniinteriors.com.au/barbara/ | I19: Public project/IMO cross-reference; not a builder's certificate. As-built 2017 information; designer beam 14.2m differs from current Oceanco page 14.5m.
A20: Y716 | B20: SHODAN | C20: 1012919 | D20: 2019 | E20: Included — identified vessel | F20: First-hand vessel photograph | G20: Y716 | H20: https://www.shipspotting.com/photos/3245295 | I20: Public project/IMO cross-reference; not a builder's certificate. Original name DreAMBoat; not the 111m Y726.
A21: Y717 | B21: LUNA | C21: 1013066 | D21: 2018 | E21: Included — identified vessel | F21: Project participant | G21: TC | H21: https://tech-consul.nl/projects | I21: Public project/IMO cross-reference; not a builder's certificate. Indexed project portfolio used for yard-code mapping only; rounded project lengths are not preferred dimensions.
A22: Y718 | B22: Bravo Eugenia | C22: 1012921 | D22: 2018 | E22: Included — identified vessel | F22: First-hand construction video | G22: Y718 | H22: https://www.youtube.com/watch?v=DD-N64-xotE | I22: Public project/IMO cross-reference; not a builder's certificate.
A23: Y719 | B23: Infinity | C23: 9817896 | D23: 2022 | E23: Included — identified vessel | F23: Refit contractor | G23: PRO | H23: https://www.proyacht.nl/custom-yacht-refit-portfolio/ | I23: Public project/IMO cross-reference; not a builder's certificate. Indexed portfolio identifies Y709 and Y719. Historical 91.5m Draak dimension is not the current builder LOA.
A24: Y720 | B24: Seven Seas | C24: 9840178 | D24: 2023 | E24: Included — identified vessel | F24: First-hand vessel photograph / post | G24: Y720 | H24: https://www.facebook.com/dutchyachting/posts/the-109m-3576-seven-seas-y720-launched-on-11-march-2022-returned-to-oceancos-dry/553672826787162/ | I24: Public project/IMO cross-reference; not a builder's certificate. Historical launch record; project delivery year is sourced separately from Oceanco.
A25: Y721 | B25: Koru | C25: 9857298 | D25: 2023 | E25: Included — identified vessel | F25: Project participant | G25: TC | H25: https://tech-consul.nl/projects | I25: Public project/IMO cross-reference; not a builder's certificate. Indexed project portfolio used for yard-code mapping only; rounded project lengths are not preferred dimensions.
A26: Y722 | B26: Leviathan | C26: 9921491 | D26: 2025 | E26: Included — identified vessel | F26: Naval architect | G26: LAT722 | H26: https://www.lateral.engineering/projects/leviathan/ | I26: Public project/IMO cross-reference; not a builder's certificate.
A27: Y723 | B27: Unmapped | E27: Unresolved numerical slot | F27: No verified mapping captured | I27: No vessel assigned in this workbook. Do not infer an unbuilt, cancelled or confidential project from the numbering gap.
A28: Y724 | B28: Unmapped | E28: Unresolved numerical slot | F28: No verified mapping captured | I28: No vessel assigned in this workbook. Do not infer an unbuilt, cancelled or confidential project from the numbering gap.
A29: Y725 | B29: Unmapped | E29: Unresolved numerical slot | F29: No verified mapping captured | I29: No vessel assigned in this workbook. Do not infer an unbuilt, cancelled or confidential project from the numbering gap.
A30: Y726 | B30: DreAMBoat | C30: 9967093 | D30: 2025 | E30: Included — identified vessel | F30: Naval architect | G30: LAT726 | H30: https://www.lateral.engineering/projects/y726-364ft/ | I30: Public project/IMO cross-reference; not a builder's certificate. Project page originally written before delivery; delivered name/year come from Oceanco.

Sheet Field Evidence
A1: FIELD EVIDENCE | TRACEABLE OBSERVATIONS
A2: One sourced observation per row • alternate values are retained rather than overwritten • filter by IMO and field to reconcile a vessel
A4: Yard ID | B4: Vessel | C4: IMO | D4: Field | E4: Observed value | F4: Unit | G4: Observation basis | H4: Qualification | I4: Source ID | J4: Source URL | K4: Checked on
A5: Y701 | B5: Batello | C5: 1009118 | D5: Yard code | E5: Y701 | G5: Public build-to-vessel cross-reference | H5: No builder certificate inspected. | I5: Y701 | J5: https://iyc.com/charter/batello/ | K5: 46290
A6: Y701 | B6: Batello | C6: 1009118 | D6: Current published name | E6: Batello | G6: Builder fleet publication | H6: Name may change after retrieval. | I6: B701 | J6: https://www.oceancoyacht.com/fleet/batello/ | K6: 46290
A7: Y701 | B7: Batello | C7: 1009118 | D7: Former names / aliases | E7: Amevi; Aalto | G7: Published name history / alias | H7: Not a certified complete sequence; dates not inferred. | I7: V701 | J7: https://www.vesselfinder.com/vessels/details/1009118 | K7: 46290
A8: Y701 | B8: Batello | C8: 1009118 | D8: Delivered | E8: 2007 | F8: year | G8: Builder delivery year | H8: Do not equate with keel-laying or launch year. | I8: B701 | J8: https://www.oceancoyacht.com/fleet/batello/ | K8: 46290
A9: Y701 | B9: Batello | C9: 1009118 | D9: IMO | E9: 1009118 | G9: Database static vessel particulars | H9: Checksum passed; checksum does not independently confirm identity. | I9: V701 | J9: https://www.vesselfinder.com/vessels/details/1009118 | K9: 46290
A10: Y701 | B10: Batello | C10: 1009118 | D10: MMSI | E10: 538070869 | G10: Published radio identity | H10: Published database identity; current registry/radio licence not inspected. | I10: V701 | J10: https://www.vesselfinder.com/vessels/details/1009118 | K10: 46290
A11: Y701 | B11: Batello | C11: 1009118 | D11: Call sign | E11: V7YZ2 | G11: Published radio identity | H11: Published database identity; current registry/radio licence not inspected. | I11: V701 | J11: https://www.vesselfinder.com/vessels/details/1009118 | K11: 46290
A12: Y701 | B12: Batello | C12: 1009118 | D12: Flag | E12: Marshall Islands | G12: Published flag / AIS identity | H12: Published database identity; current registry/radio licence not inspected. | I12: V701 | J12: https://www.vesselfinder.com/vessels/details/1009118 | K12: 46290
A13: Y701 | B13: Batello | C13: 1009118 | D13: Preferred published LOA | E13: 80 | F13: m | G13: Builder published overall length | H13: Not independently measured or certificate-verified. | I13: B701 | J13: https://www.oceancoyacht.com/fleet/batello/ | K13: 46290
A14: Y701 | B14: Batello | C14: 1009118 | D14: Preferred published beam | E14: 14.2 | F14: m | G14: Builder published overall beam | H14: Not moulded breadth unless source explicitly says so. | I14: B701 | J14: https://www.oceancoyacht.com/fleet/batello/ | K14: 46290
A15: Y701 | B15: Batello | C15: 1009118 | D15: Working gross tonnage | E15: 2310 | F15: GT | G15: Database static GT | H15: GT is not mass/displacement. | I15: V701 | J15: https://www.vesselfinder.com/vessels/details/1009118 | K15: 46290
A16: Y701 | B16: Batello | C16: 1009118 | D16: Database static LOA | E16: 80 | F16: m | G16: Database static specification, not AIS dimensions | H16: Builder beam 14.2m vs database 12.0m. Broker top-speed values conflict (19/20kn). | I16: V701 | J16: https://www.vesselfinder.com/vessels/details/1009118 | K16: 46290
A17: Y701 | B17: Batello | C17: 1009118 | D17: Database static beam | E17: 12 | F17: m | G17: Database static specification, not AIS dimensions | H17: Builder beam 14.2m vs database 12.0m. Broker top-speed values conflict (19/20kn). | I17: V701 | J17: https://www.vesselfinder.com/vessels/details/1009118 | K17: 46290
A18: Y701 | B18: Batello | C18: 1009118 | D18: Database static GT | E18: 2310 | F18: GT | G18: Database static specification | H18: Not a current International Tonnage Certificate. | I18: V701 | J18: https://www.vesselfinder.com/vessels/details/1009118 | K18: 46290
A19: Y701 | B19: Batello | C19: 1009118 | D19: Database deadweight | E19: 395 | F19: t | G19: Database static specification | H19: Deadweight is not displacement or gross tonnage. | I19: V701 | J19: https://www.vesselfinder.com/vessels/details/1009118 | K19: 46290
A20: Y701 | B20: Batello | C20: 1009118 | D20: Hull material | E20: Steel | G20: Published specification; not certificate-verified | I20: Y701 | J20: https://iyc.com/charter/batello/ | K20: 46290
A21: Y701 | B21: Batello | C21: 1009118 | D21: Exterior design | E21: Nuvolari Lenard | G21: Builder design credit; original build unless expressly noted | I21: B701 | J21: https://www.oceancoyacht.com/fleet/batello/ | K21: 46290
A22: Y701 | B22: Batello | C22: 1009118 | D22: Interior design | E22: Alberto Pinto (original) | G22: Builder design credit; may not describe later refit | I22: B701 | J22: https://www.oceancoyacht.com/fleet/batello/ | K22: 46290
A23: Y701 | B23: Batello | C23: 1009118 | D23: Cruising speed | E23: 14 | F23: kn | G23: Published specification; not certificate-verified | I23: Y701 | J23: https://iyc.com/charter/batello/ | K23: 46290
A24: Y701 | B24: Batello | C24: 1009118 | D24: Maximum motor speed | E24: 20 | F24: kn | G24: Published specification; not certificate-verified | H24: 20kn in specification table; same page narrative says 19kn. | I24: Y701 | J24: https://iyc.com/charter/batello/ | K24: 46290
A25: Y701 | B25: Batello | C25: 1009118 | D25: Published guests | E25: 12 | F25: persons | G25: Published specification; not certificate-verified | I25: Y701 | J25: https://iyc.com/charter/batello/ | K25: 46290
A26: Y701 | B26: Batello | C26: 1009118 | D26: Published guest cabins | E26: 9 | F26: cabins | G26: Published specification; not certificate-verified | I26: Y701 | J26: https://iyc.com/charter/batello/ | K26: 46290
A27: Y701 | B27: Batello | C27: 1009118 | D27: Published crew | E27: 26 | F27: persons | G27: Published specification; not certificate-verified | I27: Y701 | J27: https://iyc.com/charter/batello/ | K27: 46290
A28: Y701 | B28: Batello | C28: 1009118 | D28: Latest refit/rebuild identified | E28: 2025 | F28: year | G28: Published specification; not certificate-verified | I28: Y701 | J28: https://iyc.com/charter/batello/ | K28: 46290
A29: Y701 | B29: Batello | C29: 1009118 | D29: Selected publicly described features | E29: Retractable zero-speed stabilisers; interior refit by FM Architettura | G29: Published specification; not certificate-verified | I29: Y701 | J29: https://iyc.com/charter/batello/ | K29: 46290
A30: Y702 | B30: Alfa Nero | C30: 1009376 | D30: Yard code | E30: Y702 | G30: Public build-to-vessel cross-reference | H30: No builder certificate inspected. | I30: Y702 | J30: https://www.yachtfocus.com/it/barca/2007-oceanco-y702-10043681/ | K30: 46290
A31: Y702 | B31: Alfa Nero | C31: 1009376 | D31: Current published name | E31: Alfa Nero | G31: Builder fleet publication | H31: Name may change after retrieval. | I31: B702 | J31: https://www.oceancoyacht.com/fleet/alfa-nero/ | K31: 46290
A32: Y702 | B32: Alfa Nero | C32: 1009376 | D32: Delivered | E32: 2007 | F32: year | G32: Builder delivery year | H32: Do not equate with keel-laying or launch year. | I32: B702 | J32: https://www.oceancoyacht.com/fleet/alfa-nero/ | K32: 46290
A33: Y702 | B33: Alfa Nero | C33: 1009376 | D33: IMO | E33: 1009376 | G33: Database static vessel particulars | H33: Checksum passed; checksum does not independently confirm identity. | I33: V702 | J33: https://www.vesselfinder.com/vessels/details/1009376 | K33: 46290
A34: Y702 | B34: Alfa Nero | C34: 1009376 | D34: MMSI | E34: 249108000 | G34: Published radio identity | H34: Published database identity; current registry/radio licence not inspected. | I34: V702 | J34: https://www.vesselfinder.com/vessels/details/1009376 | K34: 46290
A35: Y702 | B35: Alfa Nero | C35: 1009376 | D35: Call sign | E35: 9HA6112 | G35: Published radio identity | H35: Published database identity; current registry/radio licence not inspected. | I35: V702 | J35: https://www.vesselfinder.com/vessels/details/1009376 | K35: 46290
A36: Y702 | B36: Alfa Nero | C36: 1009376 | D36: Flag | E36: Malta | G36: Published flag / AIS identity | H36: Published database identity; current registry/radio licence not inspected. | I36: V702 | J36: https://www.vesselfinder.com/vessels/details/1009376 | K36: 46290
A37: Y702 | B37: Alfa Nero | C37: 1009376 | D37: Preferred published LOA | E37: 82 | F37: m | G37: Builder published overall length | H37: Not independently measured or certificate-verified. | I37: B702 | J37: https://www.oceancoyacht.com/fleet/alfa-nero/ | K37: 46290
A38: Y702 | B38: Alfa Nero | C38: 1009376 | D38: Preferred published beam | E38: 14.2 | F38: m | G38: Builder published overall beam | H38: Not moulded breadth unless source explicitly says so. | I38: B702 | J38: https://www.oceancoyacht.com/fleet/alfa-nero/ | K38: 46290
A39: Y702 | B39: Alfa Nero | C39: 1009376 | D39: Working gross tonnage | E39: 2159 | F39: GT | G39: Database static GT | H39: GT is not mass/displacement. | I39: V702 | J39: https://www.vesselfinder.com/vessels/details/1009376 | K39: 46290
